Workbook

Sheet Method
A1: Method: indicative rooftop solar sizing, generation, savings, payback and CO2 for 20 Oxford sites
A2: OZ. Prepared 9 October 2026; checked by Zara Pashov, 10 October 2026. Workbook sheets: Method (this sheet), Inputs (every number and its source), Results (one row per site), Calculations (every step, every scenario).
A4: 1. Purpose and status
A5: To give an installer an indicative, desktop-derived estimate of system size, year-1 generation, annual saving, simple payback and CO2 avoided for 20 commercial roofs in Oxford City. These are not quotes. No site visit, meter data, structural check or grid-connection check has been made.
A7: 2. How the 20 sites were chosen (summary)
A8: Buildings were ranked with the OZ scorecard v0.3 (roof footprint area and site gap), the method that won the OZ arena run on 2 October 2026, using OpenStreetMap building outlines for Oxford City (local authority E07000178). Buildings with solar already mapped in OpenStreetMap, and sites with their own rooftop solar record in the Renewable Energy Planning Database, were removed. Zara Pashov checked the top 50 sites and 16 further large roofs on satellite imagery on 7 October 2026 and chose these 20: no panels visible, roof judged usable, occupier identified, a mix of sectors.
A10: 3. Decisions taken (Zara Pashov, 9 October 2026)
A11: a) Roof area: main building only (the one checked on satellite). Four sites have more buildings; these are not included.
A12: b) Sizing: roof-limited, i.e. what the usable roof can physically hold. Results above 1 MWp are flagged as likely limited by site demand or grid capacity.
A13: c) Self-consumption: the same three scenario values for every site (40% / 60% / 80%); no published source gives this by sector.
A14: d) Carbon: UK grid-average factor (DESNZ conversion factors), as businesses use for their own carbon reporting.
A15: e) Costs: published commercial price range for capital cost; official DECC 2015 running costs; DESNZ average business electricity price; business export tariffs from Ofgem's Smart Export Guarantee report.
... A65: Attribution: contains OpenStreetMap data © OpenStreetMap contributors, available under the Open Database Licence. Contains public sector information licensed under the Open Government Licence v3.0.

Sheet Inputs
A1: Inputs: every number the calculation uses, with its source
A2: Blue text = a typed input. Black = a formula. Yellow fill = an assumption or a value still to be confirmed. Change any blue cell and every result in the workbook updates.
A4: Parameter | B4: Symbol | C4: Low | D4: Central | E4: High | F4: Unit | G4: Source (see Method, section 8) | H4: Exact quote from the source, or how the value was derived | I4: Status
A5: Share of roof area covered by panels (module area / roof area) | B5: f | C5: =0.49*0.6 -> 0.294 | D5: 0.4 | E5: =0.66*0.7 -> 0.462 | F5: fraction | G5: Low: Bódis et al. (2019). Central: Kakoulaki et al. (2026). High: Gagnon et al. (2016). | H5: Low: "approximately half (49–64%) of EU roofs appeared to be suitable for PV" and "an additional reduction coefficient (60%) has been applied to estimate the net area"; lower bound 0.49 × 0.60. Central: for non-residential buildings "the PV installations were set at 40% of the total rooftop area"; "Spacing between modules and module racks is taken into account in the 25% or 40% installation fraction". High: "49% suitable for medium buildings and 66% for large buildings" and "For flat roofs, the ratio of module area to roof area was assumed to be 0.7"; 0.66 × 0.70. | I5: VERIFIED (quotes opened 09/10/2026)
A6: Module power density | B6: rho | C6: =ROUND($H$25,-1) -> 230 | D6: =ROUND($H$25,-1) -> 230 | E6: =ROUND($H$25,-1) -> 230 | F6: W per m² of module | G6: Median of three current module datasheets (rows 21-23), rounded to the nearest 10 W/m². | H6: Derived: rated power ÷ module area for each datasheet; midpoint of each product's range; median of the three. | I6: VERIFIED datasheets; median is derived
A7: Specific yield (annual generation per kWp) | B7: Y | C7: 922.3 | D7: 922.3 | E7: 922.3 | F7: kWh per kWp per year | G7: PVGIS v5.2 API, EC Joint Research Centre. Retrieved 02/10/2026 during the OZ arena run. | H7: Settings: lat 51.7514, lon −1.2407 (mean location of the 1,790 Oxford City buildings), peak power 1 kWp, system loss 14% (PVGIS default: "We have given a default value of 14% for the overall losses"), tilt 10°, azimuth 0° (south). Output E_y = 922.3. | I7: TO CONFIRM: re-run in the PVGIS web tool (Method, section 7)
A8: Self-consumption (share of generation used on site) | B8: s | C8: 0.4 | D8: 0.6 | E8: 0.8 | F8: fraction | G8: Assumption chosen by Zara Pashov, 09/10/2026. | H8: No published source gives self-consumption by sector. Systems here are sized to the roof, not to site demand, so very high self-use is less likely. To be tested with installers. | I8: ASSUMPTION
A9: Electricity price avoided by self-consumption | B9: p_imp | C9: 24.51 | D9: 24.51 | E9: 24.51 | F9: p per kWh | G9: DESNZ (2026a) Quarterly Energy Prices, September 2026, p. 8. | H9: "In quarter 2 2026, the average electricity price including CCL was 24.51 pence per kWh". All-business average; prices differ by size band. The quoted text does not state the VAT treatment. | I9: VERIFIED (all-business average)
A10: Export price for electricity not used on site | B10: p_exp | C10: 3 | D10: 4.1 | E10: 4.1 | F10: p per kWh | G10: Ofgem (2025) Smart Export Guarantee Annual Report, Year 5 (Apr 2024 – Mar 2025), Figures 2.1–2.3. | H10: Untied business export tariffs named in the report: EDF Variable Business 3 p/kWh (low); Octopus Business 4.1 p/kWh (central and high). These are 2024-25 offers. | I10: VERIFIED (2024-25 tariffs)
A11: Capital cost (installed) | B11: c | C11: 1100 | D11: =($C$11+$E$11)/2 -> 900 | E11: 700 | F11: £ per kWp | G11: Joju Solar (2026) Commercial rooftop solar (trade source). | H11: "the average cost of a commercial rooftop solar installation in the UK is between £700 and £1,100 per kilowatt peak (kWp), with larger installations typically costing less per kWp". Central = midpoint. Joju attributes the figure to the Solar Trade Association; VAT not stated. No official figure newer than 2015 was found. | I11: VERIFIED wording; trade source
A12: Operation and maintenance cost | B12: o | C12: 11.4 | D12: 9.5 | E12: 7.6 | F12: £ per kW per year (2014 prices) | G12: Parsons Brinckerhoff for DECC (2015) Small-Scale Generation Costs Update, section 2.2.4.8. | H12: Band 250–5,000 kW: low 7.6, central 9.5, high 11.4 £/kW/yr. Opex "should include labour, planned maintenance and lifecycle replacement costs". The pessimistic (Low) scenario uses the high cost. 2014 prices, not inflated. | I12: VERIFIED; dated (2014 prices)
A13: Carbon factor for UK grid electricity | B13: g | C13: 0.13096 | D13: 0.13096 | E13: 0.13096 | F13: kg CO2e per kWh | G13: DESNZ (2026b) 2026 GHG conversion factors methodology report, Table 9, p. 36. | H13: Row "2025", electricity GENERATED, total = 0.13096 kg CO2e/kWh (UK grid average, 2025 data). Transmission and distribution losses (0.01299) are not added. | I13: VERIFIED
A14: Annual degradation of panel output (not applied) | B14: d | C14: 0.005 | D14: 0.005 | E14: 0.005 | F14: per year | G14: Jordan and Kurtz (2013). | H14: "Nearly 2000 degradation rates… showing a median value of 0.5%/year." Not applied: all results are year 1. | I14: VERIFIED; documented only
A15: Flag systems larger than | B15: flag | C15: 1000 | D15: 1000 | E15: 1000 | F15: kWp | G15: Decision by Zara Pashov, 09/10/2026. | H15: Systems are sized to the roof. Above 1 MWp they are flagged as likely limited by site demand or grid capacity. | I15: DECISION
A19: Module datasheets used for the power density (row 6)
A20: Module (datasheet) | B20: Rated power, min (W) | C20: Rated power, max (W) | D20: Length (mm) | E20: Width (mm) | F20: W per m², min | G20: W per m², max | H20: Midpoint W per m² | I20: Source URL
A21: LONGi LR7-54HVH 480-500 M (datasheet dated 08/04/2025, marked draft) | B21: 480 | C21: 500 | D21: 1800 | E21: 1134 | F21: =B21/(D21/1000*E21/1000) -> 235.15579 | G21: =C21/(D21/1000*E21/1000) -> 244.95395 | H21: =(F21+G21)/2 -> 240.05487 | I21: https://static.longi.com/LR_7_54_HVH_480_500_M_BGV_01_20250408_BGV_02_568afe65cb.pdf
A22: Jinko Tiger Neo JKM435-460N-54HL4R-(V) (2024) | B22: 435 | C22: 460 | D22: 1762 | E22: 1134 | F22: =B22/(D22/1000*E22/1000) -> 217.70595 | G22: =C22/(D22/1000*E22/1000) -> 230.21779 | H22: =(F22+G22)/2 -> 223.96187 | I22: https://www.jinkosolar.com/uploads/JKM435-460N-54HL4R-(V)-F8-EN.pdf
A23: Trina Vertex N TSM-NEG19RC.20 (2025) | B23: 610 | C23: 635 | D23: 2382 | E23: 1134 | F23: =B23/(D23/1000*E23/1000) -> 225.82656 | G23: =C23/(D23/1000*E23/1000) -> 235.08175 | H23: =(F23+G23)/2 -> 230.45416 | I23: https://static.trinasolar.com/sites/default/files/DT-M-0045_Datasheet_Vertex_NEG19RC.20_EN_2025_B.pdf
G25: Median of midpoints | H25: =MEDIAN(H21:H23) -> 230.45416

Sheet Results
A1: Oxford City: indicative rooftop solar sizing, generation, savings, payback and CO2 for 20 checked sites
A2: Checked by Zara Pashov, 10 October 2026. Indicative desktop estimates from public data, not quotes. Low / Central / High are bundled scenarios (see Method). Figures are for year 1. Inputs and sources: Inputs sheet.
A4: Rank (check sheet) | B4: Site | C4: Found in tab | D4: OSM building type | E4: Buildings on site | F4: OSM footprint, main building (m²) | G4: Roof area used (m²) | H4: Roof area source | I4: Sizing status | J4: Satellite check (Zara, 7 Oct 2026) | K4: System size (kWp) | N4: Generation (MWh/yr) | Q4: Net saving (£/yr) | T4: Simple payback (years) | W4: CO2e avoided (t/yr) | Z4: Flag | AA4: Satellite view
K5: Low | L5: Central | M5: High | N5: Low | O5: Central | P5: High | Q5: Low | R5: Central | S5: High | T5: Low | U5: Central | V5: High | W5: Low | X5: Central | Y5: High
A6: 1 | B6: Unipart | C6: Top 50 | D6: industrial | E6: 1 | F6: 9774 | G6: =F6 -> 9774 | H6: OpenStreetMap building outline (main building only) | I6: Sized | J6: No panels visible; roof usable: Yes | K6: =IF(Calculations!I5="","",Calculations!I5) -> 660.91788 | L6: =IF(Calculations!I6="","",Calculations!I6) -> 899.208 | M6: =IF(Calculations!I7="","",Calculations!I7) -> 1038.5852 | N6: =IF(Calculations!K5="","",Calculations!K5/1000) -> 609.56456 | O6: =IF(Calculations!K6="","",Calculations!K6/1000) -> 829.33954 | P6: =IF(Calculations!K7="","",Calculations!K7/1000) -> 957.88717 | Q6: =IF(Calculations!T5="","",Calculations!T5) -> 63199.408 | R6: =IF(Calculations!T6="","",Calculations!T6) -> 127021.36 | S6: =IF(Calculations!T7="","",Calculations!T7) -> 187783.94 | T6: =IF(Calculations!W5="","",Calculations!W5) -> 11.503425 | U6: =IF(Calculations!W6="","",Calculations!W6) -> 6.3712683 | V6: =IF(Calculations!W7="","",Calculations!W7) -> 3.871522 | W6: =IF(Calculations!Y5="","",Calculations!Y5) -> 79.828575 | X6: =IF(Calculations!Y6="","",Calculations!Y6) -> 108.61031 | Y6: =IF(Calculations!Y7="","",Calculations!Y7) -> 125.4449 | Z6: =IF($I6="Pending","Sizing pending: angled roof, roof planes not measured (LiDAR or survey needed)",IF(L6>Inputs!$D$15,"Central size above 1 MWp: likely limited by site demand or grid capacity",IF(M6>Inputs!$E$15,"High scenario above 1 MWp: check site demand and grid capacity",""))) -> High scenario above 1 MWp: check site demand and grid capacity | AA6: Satellite
A7: 11 | B7: Unipart Logistics Cowley | C7: Top 50 | D7: warehouse_logistics | E7: 1 | F7: 80278 | G7: =F7 -> 80278 | H7: OpenStreetMap building outline (main building only) | I7: Pending | J7: No panels visible; roof usable: Yes. Note: roofs angled might not be great for solar, array probs smaller than anticipated | K7: =IF(Calculations!I8="","",Calculations!I8) | L7: =IF(Calculations!I9="","",Calculations!I9) | M7: =IF(Calculations!I10="","",Calculations!I10) | N7: =IF(Calculations!K8="","",Calculations!K8/1000) | O7: =IF(Calculations!K9="","",Calculations!K9/1000) | P7: =IF(Calculations!K10="","",Calculations!K10/1000) | Q7: =IF(Calculations!T8="","",Calculations!T8) | R7: =IF(Calculations!T9="","",Calculations!T9) | S7: =IF(Calculations!T10="","",Calculations!T10) | T7: =IF(Calculations!W8="","",Calculations!W8) | U7: =IF(Calculations!W9="","",Calculations!W9) | V7: =IF(Calculations!W10="","",Calculations!W10) | W7: =IF(Calculations!Y8="","",Calculations!Y8) | X7: =IF(Calculations!Y9="","",Calculations!Y9) | Y7: =IF(Calculations!Y10="","",Calculations!Y10) | Z7: =IF($I7="Pending","Sizing pending: angled roof, roof planes not measured (LiDAR or survey needed)",IF(L7>Inputs!$D$15,"Central size above 1 MWp: likely limited by site demand or grid capacity",IF(M7>Inputs!$E$15,"High scenario above 1 MWp: check site demand and grid capacity",""))) -> Sizing pending: angled roof, roof planes not measured (LiDAR or survey needed) | AA7: Satellite
A8: 12 | B8: Sainsbury's | C8: Top 50 | D8: retail | E8: 1 | F8: 8401 | G8: 5488 | H8: Zara Pashov, measured on satellite imagery, 7 Oct 2026 (OSM outline 8,401 m² judged too large) | I8: Sized | J8: No panels visible; roof usable: Yes. Note: I think the roof size is smaller than this estimate, I estimate 5488m2 | K8: =IF(Calculations!I11="","",Calculations!I11) -> 371.09856 | L8: =IF(Calculations!I12="","",Calculations!I12) -> 504.896 | M8: =IF(Calculations!I13="","",Calculations!I13) -> 583.15488 | N8: =IF(Calculations!K11="","",Calculations!K11/1000) -> 342.2642 | O8: =IF(Calculations!K12="","",Calculations!K12/1000) -> 465.66558 | P8: =IF(Calculations!K13="","",Calculations!K13/1000) -> 537.84375 | Q8: =IF(Calculations!T11="","",Calculations!T11) -> 35485.814 | R8: =IF(Calculations!T12="","",Calculations!T12) -> 71321.184 | S8: =IF(Calculations!T13="","",Calculations!T13) -> 105438.74 | T8: =IF(Calculations!W11="","",Calculations!W11) -> 11.503425 | U8: =IF(Calculations!W12="","",Calculations!W12) -> 6.3712683 | V8: =IF(Calculations!W13="","",Calculations!W13) -> 3.871522 | W8: =IF(Calculations!Y11="","",Calculations!Y11) -> 44.82292 | X8: =IF(Calculations!Y12="","",Calculations!Y12) -> 60.983564 | Y8: =IF(Calculations!Y13="","",Calculations!Y13) -> 70.436017 | Z8: =IF($I8="Pending","Sizing pending: angled roof, roof planes not measured (LiDAR or survey needed)",IF(L8>Inputs!$D$15,"Central size above 1 MWp: likely limited by site demand or grid capacity",IF(M8>Inputs!$E$15,"High scenario above 1 MWp: check site demand and grid capacity",""))) | AA8: Satellite
A9: 50 | B9: Ozone Leisure Centre | C9: Top 50 | D9: retail | E9: 1 | F9: 11652 | G9: =F9 -> 11652 | H9: OpenStreetMap building outline (main building only) | I9: Sized | J9: No panels visible; roof usable: Yes | K9: =IF(Calculations!I14="","",Calculations!I14) -> 787.90824 | L9: =IF(Calculations!I15="","",Calculations!I15) -> 1071.984 | M9: =IF(Calculations!I16="","",Calculations!I16) -> 1238.1415 | N9: =IF(Calculations!K14="","",Calculations!K14/1000) -> 726.68777 | O9: =IF(Calculations!K15="","",Calculations!K15/1000) -> 988.69084 | P9: =IF(Calculations!K16="","",Calculations!K16/1000) -> 1141.9379 | Q9: =IF(Calculations!T14="","",Calculations!T14) -> 75342.695 | R9: =IF(Calculations!T15="","",Calculations!T15) -> 151427.56 | S9: =IF(Calculations!T16="","",Calculations!T16) -> 223865.2 | T9: =IF(Calculations!W14="","",Calculations!W14) -> 11.503425 | U9: =IF(Calculations!W15="","",Calculations!W15) -> 6.3712683 | V9: =IF(Calculations!W16="","",Calculations!W16) -> 3.871522 | W9: =IF(Calculations!Y14="","",Calculations!Y14) -> 95.16703 | X9: =IF(Calculations!Y15="","",Calculations!Y15) -> 129.47895 | Y9: =IF(Calculations!Y16="","",Calculations!Y16) -> 149.54819 | Z9: =IF($I9="Pending","Sizing pending: angled roof, roof planes not measured (LiDAR or survey needed)",IF(L9>Inputs!$D$15,"Central size above 1 MWp: likely limited by site demand or grid capacity",IF(M9>Inputs!$E$15,"High scenario above 1 MWp: check site demand and grid capacity",""))) -> Central size above 1 MWp: likely limited by site demand or grid capacity | AA9: Satellite
A10: 26 | B10: Kassam Stadium | C10: Top 50 | D10: hospitality_leisure | E10: 3 | F10: 5428 | G10: =F10 -> 5428 | H10: OpenStreetMap building outline (main building only) | I10: Sized | J10: No panels visible; roof usable: Yes | K10: =IF(Calculations!I17="","",Calculations!I17) -> 367.04136 | L10: =IF(Calculations!I18="","",Calculations!I18) -> 499.376 | M10: =IF(Calculations!I19="","",Calculations!I19) -> 576.77928 | N10: =IF(Calculations!K17="","",Calculations!K17/1000) -> 338.52225 | O10: =IF(Calculations!K18="","",Calculations!K18/1000) -> 460.57448 | P10: =IF(Calculations!K19="","",Calculations!K19/1000) -> 531.96353 | Q10: =IF(Calculations!T17="","",Calculations!T17) -> 35097.85 | R10: =IF(Calculations!T18="","",Calculations!T18) -> 70541.433 | S10: =IF(Calculations!T19="","",Calculations!T19) -> 104285.99 | T10: =IF(Calculations!W17="","",Calculations!W17) -> 11.503425 | U10: =IF(Calculations!W18="","",Calculations!W18) -> 6.3712683 | V10: =IF(Calculations!W19="","",Calculations!W19) -> 3.871522 | W10: =IF(Calculations!Y17="","",Calculations!Y17) -> 44.332873 | X10: =IF(Calculations!Y18="","",Calculations!Y18) -> 60.316835 | Y10: =IF(Calculations!Y19="","",Calculations!Y19) -> 69.665944 | Z10: =IF($I10="Pending","Sizing pending: angled roof, roof planes not measured (LiDAR or survey needed)",IF(L10>Inputs!$D$15,"Central size above 1 MWp: likely limited by site demand or grid capacity",IF(M10>Inputs!$E$15,"High scenario above 1 MWp: check site demand and grid capacity",""))) | AA10: Satellite
A11: 13 | B11: Holiday Inn | C11: Top 50 | D11: untagged_large_no_zone | E11: 1 | F11: 4424 | G11: =F11 -> 4424 | H11: OpenStreetMap building outline (main building only) | I11: Sized | J11: No panels visible; roof usable: Yes | K11: =IF(Calculations!I20="","",Calculations!I20) -> 299.15088 | L11: =IF(Calculations!I21="","",Calculations!I21) -> 407.008 | M11: =IF(Calculations!I22="","",Calculations!I22) -> 470.09424 | N11: =IF(Calculations!K20="","",Calculations!K20/1000) -> 275.90686 | O11: =IF(Calculations!K21="","",Calculations!K21/1000) -> 375.38348 | P11: =IF(Calculations!K22="","",Calculations!K22/1000) -> 433.56792 | Q11: =IF(Calculations!T20="","",Calculations!T20) -> 28605.912 | R11: =IF(Calculations!T21="","",Calculations!T21) -> 57493.607 | S11: =IF(Calculations!T22="","",Calculations!T22) -> 84996.538 | T11: =IF(Calculations!W20="","",Calculations!W20) -> 11.503425 | U11: =IF(Calculations!W21="","",Calculations!W21) -> 6.3712683 | V11: =IF(Calculations!W22="","",Calculations!W22) -> 3.871522 | W11: =IF(Calculations!Y20="","",Calculations!Y20) -> 36.132762 | X11: =IF(Calculations!Y21="","",Calculations!Y21) -> 49.16022 | Y11: =IF(Calculations!Y22="","",Calculations!Y22) -> 56.780054 | Z11: =IF($I11="Pending","Sizing pending: angled roof, roof planes not measured (LiDAR or survey needed)",IF(L11>Inputs!$D$15,"Central size above 1 MWp: likely limited by site demand or grid capacity",IF(M11>Inputs!$E$15,"High scenario above 1 MWp: check site demand and grid capacity",""))) | AA11: Satellite
A12: 24 | B12: The Oxford Academy | C12: Top 50 | D12: education | E12: 3 | F12: 9070 | G12: =F12 -> 9070 | H12: OpenStreetMap building outline (main building only) | I12: Sized | J12: No panels visible; roof usable: Yes | K12: =IF(Calculations!I23="","",Calculations!I23) -> 613.3134 | L12: =IF(Calculations!I24="","",Calculations!I24) -> 834.44 | M12: =IF(Calculations!I25="","",Calculations!I25) -> 963.7782 | N12: =IF(Calculations!K23="","",Calculations!K23/1000) -> 565.65895 | O12: =IF(Calculations!K24="","",Calculations!K24/1000) -> 769.60401 | P12: =IF(Calculations!K25="","",Calculations!K25/1000) -> 888.89263 | Q12: =IF(Calculations!T23="","",Calculations!T23) -> 58647.292 | R12: =IF(Calculations!T24="","",Calculations!T24) -> 117872.29 | S12: =IF(Calculations!T25="","",Calculations!T25) -> 174258.27 | T12: =IF(Calculations!W23="","",Calculations!W23) -> 11.503425 | U12: =IF(Calculations!W24="","",Calculations!W24) -> 6.3712683 | V12: =IF(Calculations!W25="","",Calculations!W25) -> 3.871522 | W12: =IF(Calculations!Y23="","",Calculations!Y23) -> 74.078696 | X12: =IF(Calculations!Y24="","",Calculations!Y24) -> 100.78734 | Y12: =IF(Calculations!Y25="","",Calculations!Y25) -> 116.40938 | Z12: =IF($I12="Pending","Sizing pending: angled roof, roof planes not measured (LiDAR or survey needed)",IF(L12>Inputs!$D$15,"Central size above 1 MWp: likely limited by site demand or grid capacity",IF(M12>Inputs!$E$15,"High scenario above 1 MWp: check site demand and grid capacity",""))) | AA12: Satellite
A13: 28 | B13: Oxford Telephone Exchange | C13: Top 50 | D13: untagged_in_commercial_zone | E13: 1 | F13: 3900 | G13: =F13 -> 3900 | H13: OpenStreetMap building outline (main building only) | I13: Sized | J13: No panels visible; roof usable: Yes | K13: =IF(Calculations!I26="","",Calculations!I26) -> 263.718 | L13: =IF(Calculations!I27="","",Calculations!I27) -> 358.8 | M13: =IF(Calculations!I28="","",Calculations!I28) -> 414.414 | N13: =IF(Calculations!K26="","",Calculations!K26/1000) -> 243.22711 | O13: =IF(Calculations!K27="","",Calculations!K27/1000) -> 330.92124 | P13: =IF(Calculations!K28="","",Calculations!K28/1000) -> 382.21403 | Q13: =IF(Calculations!T26="","",Calculations!T26) -> 25217.689 | R13: =IF(Calculations!T27="","",Calculations!T27) -> 50683.786 | S13: =IF(Calculations!T28="","",Calculations!T28) -> 74929.136 | T13: =IF(Calculations!W26="","",Calculations!W26) -> 11.503425 | U13: =IF(Calculations!W27="","",Calculations!W27) -> 6.3712683 | V13: =IF(Calculations!W28="","",Calculations!W28) -> 3.871522 | W13: =IF(Calculations!Y26="","",Calculations!Y26) -> 31.853023 | X13: =IF(Calculations!Y27="","",Calculations!Y27) -> 43.337446 | Y13: =IF(Calculations!Y28="","",Calculations!Y28) -> 50.05475 | Z13: =IF($I13="Pending","Sizing pending: angled roof, roof planes not measured (LiDAR or survey needed)",IF(L13>Inputs!$D$15,"Central size above 1 MWp: likely limited by site demand or grid capacity",IF(M13>Inputs!$E$15,"High scenario above 1 MWp: check site demand and grid capacity",""))) | AA13: Satellite
A14: 5 | B14: Oxford Business Park (OxBio Hub) | C14: Top 50 | D14: untagged_in_commercial_zone | E14: 1 | F14: 3243 | G14: =F14 -> 3243 | H14: OpenStreetMap building outline (main building only) | I14: Sized | J14: No panels visible; roof usable: Yes | K14: =IF(Calculations!I29="","",Calculations!I29) -> 219.29166 | L14: =IF(Calculations!I30="","",Calculations!I30) -> 298.356 | M14: =IF(Calculations!I31="","",Calculations!I31) -> 344.60118 | N14: =IF(Calculations!K29="","",Calculations!K29/1000) -> 202.2527 | O14: =IF(Calculations!K30="","",Calculations!K30/1000) -> 275.17374 | P14: =IF(Calculations!K31="","",Calculations!K31/1000) -> 317.82567 | Q14: =IF(Calculations!T29="","",Calculations!T29) -> 20969.478 | R14: =IF(Calculations!T30="","",Calculations!T30) -> 42145.517 | S14: =IF(Calculations!T31="","",Calculations!T31) -> 62306.459 | T14: =IF(Calculations!W29="","",Calculations!W29) -> 11.503425 | U14: =IF(Calculations!W30="","",Calculations!W30) -> 6.3712683 | V14: =IF(Calculations!W31="","",Calculations!W31) -> 3.871522 | W14: =IF(Calculations!Y29="","",Calculations!Y29) -> 26.487013 | X14: =IF(Calculations!Y30="","",Calculations!Y30) -> 36.036753 | Y14: =IF(Calculations!Y31="","",Calculations!Y31) -> 41.62245 | Z14: =IF($I14="Pending","Sizing pending: angled roof, roof planes not measured (LiDAR or survey needed)",IF(L14>Inputs!$D$15,"Central size above 1 MWp: likely limited by site demand or grid capacity",IF(M14>Inputs!$E$15,"High scenario above 1 MWp: check site demand and grid capacity",""))) | AA14: Satellite
A15: 7 | B15: Oxford Business Park (John Wiley & Sons) | C15: Top 50 | D15: commercial_office | E15: 1 | F15: 2784 | G15: =F15 -> 2784 | H15: OpenStreetMap building outline (main building only) | I15: Sized | J15: No panels visible; roof usable: Yes | K15: =IF(Calculations!I32="","",Calculations!I32) -> 188.25408 | L15: =IF(Calculations!I33="","",Calculations!I33) -> 256.128 | M15: =IF(Calculations!I34="","",Calculations!I34) -> 295.82784 | N15: =IF(Calculations!K32="","",Calculations!K32/1000) -> 173.62674 | O15: =IF(Calculations!K33="","",Calculations!K33/1000) -> 236.22685 | P15: =IF(Calculations!K34="","",Calculations!K34/1000) -> 272.84202 | Q15: =IF(Calculations!T32="","",Calculations!T32) -> 18001.55 | R15: =IF(Calculations!T33="","",Calculations!T33) -> 36180.426 | S15: =IF(Calculations!T34="","",Calculations!T34) -> 53487.876 | T15: =IF(Calculations!W32="","",Calculations!W32) -> 11.503425 | U15: =IF(Calculations!W33="","",Calculations!W33) -> 6.3712683 | V15: =IF(Calculations!W34="","",Calculations!W34) -> 3.871522 | W15: =IF(Calculations!Y32="","",Calculations!Y32) -> 22.738158 | X15: =IF(Calculations!Y33="","",Calculations!Y33) -> 30.936269 | Y15: =IF(Calculations!Y34="","",Calculations!Y34) -> 35.731391 | Z15: =IF($I15="Pending","Sizing pending: angled roof, roof planes not measured (LiDAR or survey needed)",IF(L15>Inputs!$D$15,"Central size above 1 MWp: likely limited by site demand or grid capacity",IF(M15>Inputs!$E$15,"High scenario above 1 MWp: check site demand and grid capacity",""))) | AA15: Satellite
A16: 21 | B16: Wickes | C16: Top 50 | D16: retail | E16: 1 | F16: 2613 | G16: =F16 -> 2613 | H16: OpenStreetMap building outline (main building only) | I16: Sized | J16: No panels visible; roof usable: Yes | K16: =IF(Calculations!I35="","",Calculations!I35) -> 176.69106 | L16: =IF(Calculations!I36="","",Calculations!I36) -> 240.396 | M16: =IF(Calculations!I37="","",Calculations!I37) -> 277.65738 | N16: =IF(Calculations!K35="","",Calculations!K35/1000) -> 162.96216 | O16: =IF(Calculations!K36="","",Calculations!K36/1000) -> 221.71723 | P16: =IF(Calculations!K37="","",Calculations!K37/1000) -> 256.0834 | Q16: =IF(Calculations!T35="","",Calculations!T35) -> 16895.852 | R16: =IF(Calculations!T36="","",Calculations!T36) -> 33958.137 | S16: =IF(Calculations!T37="","",Calculations!T37) -> 50202.521 | T16: =IF(Calculations!W35="","",Calculations!W35) -> 11.503425 | U16: =IF(Calculations!W36="","",Calculations!W36) -> 6.3712683 | V16: =IF(Calculations!W37="","",Calculations!W37) -> 3.871522 | W16: =IF(Calculations!Y35="","",Calculations!Y35) -> 21.341525 | X16: =IF(Calculations!Y36="","",Calculations!Y36) -> 29.036089 | Y16: =IF(Calculations!Y37="","",Calculations!Y37) -> 33.536682 | Z16: =IF($I16="Pending","Sizing pending: angled roof, roof planes not measured (LiDAR or survey needed)",IF(L16>Inputs!$D$15,"Central size above 1 MWp: likely limited by site demand or grid capacity",IF(M16>Inputs!$E$15,"High scenario above 1 MWp: check site demand and grid capacity",""))) | AA16: Satellite
A17: 30 | B17: Storage King Oxford - Self Storage Units | C17: Top 50 | D17: warehouse_logistics | E17: 1 | F17: 3558 | G17: =F17 -> 3558 | H17: OpenStreetMap building outline (main building only) | I17: Sized | J17: No panels visible; roof usable: Yes. Note: no name given, but it is logisitcs | K17: =IF(Calculations!I38="","",Calculations!I38) -> 240.59196 | L17: =IF(Calculations!I39="","",Calculations!I39) -> 327.336 | M17: =IF(Calculations!I40="","",Calculations!I40) -> 378.07308 | N17: =IF(Calculations!K38="","",Calculations!K38/1000) -> 221.89796 | O17: =IF(Calculations!K39="","",Calculations!K39/1000) -> 301.90199 | P17: =IF(Calculations!K40="","",Calculations!K40/1000) -> 348.6968 | Q17: =IF(Calculations!T38="","",Calculations!T38) -> 23006.291 | R17: =IF(Calculations!T39="","",Calculations!T39) -> 46239.208 | S17: =IF(Calculations!T40="","",Calculations!T40) -> 68358.427 | T17: =IF(Calculations!W38="","",Calculations!W38) -> 11.503425 | U17: =IF(Calculations!W39="","",Calculations!W39) -> 6.3712683 | V17: =IF(Calculations!W40="","",Calculations!W40) -> 3.871522 | W17: =IF(Calculations!Y38="","",Calculations!Y38) -> 29.059757 | X17: =IF(Calculations!Y39="","",Calculations!Y39) -> 39.537085 | Y17: =IF(Calculations!Y40="","",Calculations!Y40) -> 45.665333 | Z17: =IF($I17="Pending","Sizing pending: angled roof, roof planes not measured (LiDAR or survey needed)",IF(L17>Inputs!$D$15,"Central size above 1 MWp: likely limited by site demand or grid capacity",IF(M17>Inputs!$E$15,"High scenario above 1 MWp: check site demand and grid capacity",""))) | AA17: Satellite
A18: 44 | B18: Nuffield Trade and Industrial Park (Royal Mail East Oxford Delivery Office) | C18: Top 50 | D18: untagged_in_industrial_zone | E18: 1 | F18: 1897 | G18: =F18 -> 1897 | H18: OpenStreetMap building outline (main building only) | I18: Sized | J18: No panels visible; roof usable: Yes | K18: =IF(Calculations!I41="","",Calculations!I41) -> 128.27514 | L18: =IF(Calculations!I42="","",Calculations!I42) -> 174.524 | M18: =IF(Calculations!I43="","",Calculations!I43) -> 201.57522 | N18: =IF(Calculations!K41="","",Calculations!K41/1000) -> 118.30816 | O18: =IF(Calculations!K42="","",Calculations!K42/1000) -> 160.96349 | P18: =IF(Calculations!K43="","",Calculations!K43/1000) -> 185.91283 | Q18: =IF(Calculations!T41="","",Calculations!T41) -> 12266.142 | R18: =IF(Calculations!T42="","",Calculations!T42) -> 24653.113 | S18: =IF(Calculations!T43="","",Calculations!T43) -> 36446.3 | T18: =IF(Calculations!W41="","",Calculations!W41) -> 11.503425 | U18: =IF(Calculations!W42="","",Calculations!W42) -> 6.3712683 | V18: =IF(Calculations!W43="","",Calculations!W43) -> 3.871522 | W18: =IF(Calculations!Y41="","",Calculations!Y41) -> 15.493637 | X18: =IF(Calculations!Y42="","",Calculations!Y42) -> 21.079778 | Y18: =IF(Calculations!Y43="","",Calculations!Y43) -> 24.347144 | Z18: =IF($I18="Pending","Sizing pending: angled roof, roof planes not measured (LiDAR or survey needed)",IF(L18>Inputs!$D$15,"Central size above 1 MWp: likely limited by site demand or grid capacity",IF(M18>Inputs!$E$15,"High scenario above 1 MWp: check site demand and grid capacity",""))) | AA18: Satellite
A19: 39 | B19: Unicol Engineering | C19: Top 50 | D19: commercial_office | E19: 1 | F19: 1652 | G19: =F19 -> 1652 | H19: OpenStreetMap building outline (main building only) | I19: Sized | J19: No panels visible; roof usable: Yes | K19: =IF(Calculations!I44="","",Calculations!I44) -> 111.70824 | L19: =IF(Calculations!I45="","",Calculations!I45) -> 151.984 | M19: =IF(Calculations!I46="","",Calculations!I46) -> 175.54152 | N19: =IF(Calculations!K44="","",Calculations!K44/1000) -> 103.02851 | O19: =IF(Calculations!K45="","",Calculations!K45/1000) -> 140.17484 | P19: =IF(Calculations!K46="","",Calculations!K46/1000) -> 161.90194 | Q19: =IF(Calculations!T44="","",Calculations!T44) -> 10681.954 | R19: =IF(Calculations!T45="","",Calculations!T45) -> 21469.132 | S19: =IF(Calculations!T46="","",Calculations!T46) -> 31739.214 | T19: =IF(Calculations!W44="","",Calculations!W44) -> 11.503425 | U19: =IF(Calculations!W45="","",Calculations!W45) -> 6.3712683 | V19: =IF(Calculations!W46="","",Calculations!W46) -> 3.871522 | W19: =IF(Calculations!Y44="","",Calculations!Y44) -> 13.492614 | X19: =IF(Calculations!Y45="","",Calculations!Y45) -> 18.357297 | Y19: =IF(Calculations!Y46="","",Calculations!Y46) -> 21.202679 | Z19: =IF($I19="Pending","Sizing pending: angled roof, roof planes not measured (LiDAR or survey needed)",IF(L19>Inputs!$D$15,"Central size above 1 MWp: likely limited by site demand or grid capacity",IF(M19>Inputs!$E$15,"High scenario above 1 MWp: check site demand and grid capacity",""))) | AA19: Satellite
A20: 40 | B20: Magdalen Centre (Sherrington Buidling) | C20: Top 50 | D20: commercial_office | E20: 1 | F20: 2351 | G20: =F20 -> 2351 | H20: OpenStreetMap building outline (main building only) | I20: Sized | J20: No panels visible; roof usable: Yes | K20: =IF(Calculations!I47="","",Calculations!I47) -> 158.97462 | L20: =IF(Calculations!I48="","",Calculations!I48) -> 216.292 | M20: =IF(Calculations!I49="","",Calculations!I49) -> 249.81726 | N20: =IF(Calculations!K47="","",Calculations!K47/1000) -> 146.62229 | O20: =IF(Calculations!K48="","",Calculations!K48/1000) -> 199.48611 | P20: =IF(Calculations!K49="","",Calculations!K49/1000) -> 230.40646 | Q20: =IF(Calculations!T47="","",Calculations!T47) -> 15201.74 | R20: =IF(Calculations!T48="","",Calculations!T48) -> 30553.226 | S20: =IF(Calculations!T49="","",Calculations!T49) -> 45168.82 | T20: =IF(Calculations!W47="","",Calculations!W47) -> 11.503425 | U20: =IF(Calculations!W48="","",Calculations!W48) -> 6.3712683 | V20: =IF(Calculations!W49="","",Calculations!W49) -> 3.871522 | W20: =IF(Calculations!Y47="","",Calculations!Y47) -> 19.201655 | X20: =IF(Calculations!Y48="","",Calculations!Y48) -> 26.124701 | Y20: =IF(Calculations!Y49="","",Calculations!Y49) -> 30.17403 | Z20: =IF($I20="Pending","Sizing pending: angled roof, roof planes not measured (LiDAR or survey needed)",IF(L20>Inputs!$D$15,"Central size above 1 MWp: likely limited by site demand or grid capacity",IF(M20>Inputs!$E$15,"High scenario above 1 MWp: check site demand and grid capacity",""))) | AA20: Satellite
A21: 22 | B21: Sandhills Community Primary School | C21: Top 50 | D21: education | E21: 1 | F21: 2542 | G21: =F21 -> 2542 | H21: OpenStreetMap building outline (main building only) | I21: Sized | J21: No panels visible; roof usable: Yes | K21: =IF(Calculations!I50="","",Calculations!I50) -> 171.89004 | L21: =IF(Calculations!I51="","",Calculations!I51) -> 233.864 | M21: =IF(Calculations!I52="","",Calculations!I52) -> 270.11292 | N21: =IF(Calculations!K50="","",Calculations!K50/1000) -> 158.53418 | O21: =IF(Calculations!K51="","",Calculations!K51/1000) -> 215.69277 | P21: =IF(Calculations!K52="","",Calculations!K52/1000) -> 249.12515 | Q21: =IF(Calculations!T50="","",Calculations!T50) -> 16436.76 | R21: =IF(Calculations!T51="","",Calculations!T51) -> 33035.432 | S21: =IF(Calculations!T52="","",Calculations!T52) -> 48838.427 | T21: =IF(Calculations!W50="","",Calculations!W50) -> 11.503425 | U21: =IF(Calculations!W51="","",Calculations!W51) -> 6.3712683 | V21: =IF(Calculations!W52="","",Calculations!W52) -> 3.871522 | W21: =IF(Calculations!Y50="","",Calculations!Y50) -> 20.761637 | X21: =IF(Calculations!Y51="","",Calculations!Y51) -> 28.247125 | Y21: =IF(Calculations!Y52="","",Calculations!Y52) -> 32.625429 | Z21: =IF($I21="Pending","Sizing pending: angled roof, roof planes not measured (LiDAR or survey needed)",IF(L21>Inputs!$D$15,"Central size above 1 MWp: likely limited by site demand or grid capacity",IF(M21>Inputs!$E$15,"High scenario above 1 MWp: check site demand and grid capacity",""))) | AA21: Satellite
A22: 99 | B22: Oxford Retail Park (TESCO SUPERSTORE) | C22: Large roofs | D22: retail | E22: 1 | F22: 6954 | G22: =F22 -> 6954 | H22: OpenStreetMap building outline (main building only) | I22: Sized | J22: No panels visible; roof usable: Yes | K22: =IF(Calculations!I53="","",Calculations!I53) -> 470.22948 | L22: =IF(Calculations!I54="","",Calculations!I54) -> 639.768 | M22: =IF(Calculations!I55="","",Calculations!I55) -> 738.93204 | N22: =IF(Calculations!K53="","",Calculations!K53/1000) -> 433.69265 | O22: =IF(Calculations!K54="","",Calculations!K54/1000) -> 590.05803 | P22: =IF(Calculations!K55="","",Calculations!K55/1000) -> 681.51702 | Q22: =IF(Calculations!T53="","",Calculations!T53) -> 44965.079 | R22: =IF(Calculations!T54="","",Calculations!T54) -> 90373.089 | S22: =IF(Calculations!T55="","",Calculations!T55) -> 133604.41 | T22: =IF(Calculations!W53="","",Calculations!W53) -> 11.503425 | U22: =IF(Calculations!W54="","",Calculations!W54) -> 6.3712683 | V22: =IF(Calculations!W55="","",Calculations!W55) -> 3.871522 | W22: =IF(Calculations!Y53="","",Calculations!Y53) -> 56.796389 | X22: =IF(Calculations!Y54="","",Calculations!Y54) -> 77.273999 | Y22: =IF(Calculations!Y55="","",Calculations!Y55) -> 89.251469 | Z22: =IF($I22="Pending","Sizing pending: angled roof, roof planes not measured (LiDAR or survey needed)",IF(L22>Inputs!$D$15,"Central size above 1 MWp: likely limited by site demand or grid capacity",IF(M22>Inputs!$E$15,"High scenario above 1 MWp: check site demand and grid capacity",""))) | AA22: Satellite
A23: 103 | B23: Oxford University Press | C23: Large roofs | D23: commercial_office | E23: 7 | F23: 4584 | G23: =F23 -> 4584 | H23: OpenStreetMap building outline (main building only) | I23: Sized | J23: No panels visible; roof usable: Yes | K23: =IF(Calculations!I56="","",Calculations!I56) -> 309.97008 | L23: =IF(Calculations!I57="","",Calculations!I57) -> 421.728 | M23: =IF(Calculations!I58="","",Calculations!I58) -> 487.09584 | N23: =IF(Calculations!K56="","",Calculations!K56/1000) -> 285.8854 | O23: =IF(Calculations!K57="","",Calculations!K57/1000) -> 388.95973 | P23: =IF(Calculations!K58="","",Calculations!K58/1000) -> 449.24849 | Q23: =IF(Calculations!T56="","",Calculations!T56) -> 29640.483 | R23: =IF(Calculations!T57="","",Calculations!T57) -> 59572.942 | S23: =IF(Calculations!T58="","",Calculations!T58) -> 88070.554 | T23: =IF(Calculations!W56="","",Calculations!W56) -> 11.503425 | U23: =IF(Calculations!W57="","",Calculations!W57) -> 6.3712683 | V23: =IF(Calculations!W58="","",Calculations!W58) -> 3.871522 | W23: =IF(Calculations!Y56="","",Calculations!Y56) -> 37.439553 | X23: =IF(Calculations!Y57="","",Calculations!Y57) -> 50.938167 | Y23: =IF(Calculations!Y58="","",Calculations!Y58) -> 58.833583 | Z23: =IF($I23="Pending","Sizing pending: angled roof, roof planes not measured (LiDAR or survey needed)",IF(L23>Inputs!$D$15,"Central size above 1 MWp: likely limited by site demand or grid capacity",IF(M23>Inputs!$E$15,"High scenario above 1 MWp: check site demand and grid capacity",""))) | AA23: Satellite
A24: 61 | B24: Leonardo Royal Hotel Oxford | C24: Large roofs | D24: hospitality_leisure | E24: 2 | F24: 7218 | G24: =F24 -> 7218 | H24: OpenStreetMap building outline (main building only) | I24: Sized | J24: No panels visible; roof usable: Yes | K24: =IF(Calculations!I59="","",Calculations!I59) -> 488.08116 | L24: =IF(Calculations!I60="","",Calculations!I60) -> 664.056 | M24: =IF(Calculations!I61="","",Calculations!I61) -> 766.98468 | N24: =IF(Calculations!K59="","",Calculations!K59/1000) -> 450.15725 | O24: =IF(Calculations!K60="","",Calculations!K60/1000) -> 612.45885 | P24: =IF(Calculations!K61="","",Calculations!K61/1000) -> 707.38997 | Q24: =IF(Calculations!T59="","",Calculations!T59) -> 46672.123 | R24: =IF(Calculations!T60="","",Calculations!T60) -> 93803.991 | S24: =IF(Calculations!T61="","",Calculations!T61) -> 138676.54 | T24: =IF(Calculations!W59="","",Calculations!W59) -> 11.503425 | U24: =IF(Calculations!W60="","",Calculations!W60) -> 6.3712683 | V24: =IF(Calculations!W61="","",Calculations!W61) -> 3.871522 | W24: =IF(Calculations!Y59="","",Calculations!Y59) -> 58.952594 | X24: =IF(Calculations!Y60="","",Calculations!Y60) -> 80.207611 | Y24: =IF(Calculations!Y61="","",Calculations!Y61) -> 92.639791 | Z24: =IF($I24="Pending","Sizing pending: angled roof, roof planes not measured (LiDAR or survey needed)",IF(L24>Inputs!$D$15,"Central size above 1 MWp: likely limited by site demand or grid capacity",IF(M24>Inputs!$E$15,"High scenario above 1 MWp: check site demand and grid capacity",""))) | AA24: Satellite
A25: 52 | B25: The Manor Hospital | C25: Large roofs | D25: health | E25: 1 | F25: 4354 | G25: =F25 -> 4354 | H25: OpenStreetMap building outline (main building only) | I25: Sized | J25: No panels visible; roof usable: Yes | K25: =IF(Calculations!I62="","",Calculations!I62) -> 294.41748 | L25: =IF(Calculations!I63="","",Calculations!I63) -> 400.568 | M25: =IF(Calculations!I64="","",Calculations!I64) -> 462.65604 | N25: =IF(Calculations!K62="","",Calculations!K62/1000) -> 271.54124 | O25: =IF(Calculations!K63="","",Calculations!K63/1000) -> 369.44387 | P25: =IF(Calculations!K64="","",Calculations!K64/1000) -> 426.70767 | Q25: =IF(Calculations!T62="","",Calculations!T62) -> 28153.286 | R25: =IF(Calculations!T63="","",Calculations!T63) -> 56583.898 | S25: =IF(Calculations!T64="","",Calculations!T64) -> 83651.656 | T25: =IF(Calculations!W62="","",Calculations!W62) -> 11.503425 | U25: =IF(Calculations!W63="","",Calculations!W63) -> 6.3712683 | V25: =IF(Calculations!W64="","",Calculations!W64) -> 3.871522 | W25: =IF(Calculations!Y62="","",Calculations!Y62) -> 35.561041 | X25: =IF(Calculations!Y63="","",Calculations!Y63) -> 48.382369 | Y25: =IF(Calculations!Y64="","",Calculations!Y64) -> 55.881636 | Z25: =IF($I25="Pending","Sizing pending: angled roof, roof planes not measured (LiDAR or survey needed)",IF(L25>Inputs!$D$15,"Central size above 1 MWp: likely limited by site demand or grid capacity",IF(M25>Inputs!$E$15,"High scenario above 1 MWp: check site demand and grid capacity",""))) | AA25: Satellite
B26: Total, sized sites | G26: =SUMIF(I6:I25,"Sized",G6:G25) -> 93486 | K26: =SUM(K6:K25) -> 6321.5233 | L26: =SUM(L6:L25) -> 8600.712 | M26: =SUM(M6:M25) -> 9933.8224 | N26: =SUM(N6:N25) -> 5830.341 | O26: =SUM(O6:O25) -> 7932.4367 | P26: =SUM(P6:P25) -> 9161.9644 | Q26: =SUM(Q6:Q25) -> 604487.4 | R26: =SUM(R6:R25) -> 1214929.3 | S26: =SUM(S6:S25) -> 1796109 | W26: =SUM(W6:W25) -> 763.54145 | X26: =SUM(X6:X25) -> 1038.8319 | Y26: =SUM(Y6:Y25) -> 1199.8509
A28: Why payback is the same at every site within a scenario: every input except roof area is the same for all sites (one yield, one self-consumption share, one price, one cost per kWp), and payback does not depend on roof area. Site-specific payback needs site data, above all how much of the solar each site would use itself.

Sheet Calculations
A1: Calculations: every step for every site and scenario (formulas only; inputs come from the Inputs sheet)
A2: Scenario 1 = Low (pessimistic on every input), 2 = Central, 3 = High (optimistic on every input). Each input is picked from the Inputs sheet with INDEX(row, scenario number).
A4: Rank | B4: Site | C4: Scenario | D4: Scenario no. | E4: Sizing status | F4: Roof area used (m²) | G4: Panel cover share f | H4: Power density rho (W/m²) | I4: System size (kWp) | J4: Specific yield Y (kWh/kWp/yr) | K4: Generation (kWh/yr) | L4: Self-consumption s | M4: Used on site (kWh/yr) | N4: Exported (kWh/yr) | O4: Import price (p/kWh) | P4: Export price (p/kWh) | Q4: Gross saving (£/yr) | R4: O&M rate (£/kW/yr) | S4: O&M cost (£/yr) | T4: Net saving (£/yr) | U4: Capital cost rate (£/kWp) | V4: Capital cost (£) | W4: Simple payback (years) | X4: Carbon factor (kg CO2e/kWh) | Y4: CO2e avoided (t/yr)
A5: 1 | B5: Unipart | C5: Low | D5: 1 | E5: =Results!$I$6 -> Sized | F5: =Results!$G$6 -> 9774 | G5: =INDEX(Inputs!$C$5:$E$5,1,$D5) -> 0.294 | H5: =INDEX(Inputs!$C$6:$E$6,1,$D5) -> 230 | I5: =IF($E5="Pending","",F5*G5*H5/1000) -> 660.91788 | J5: =INDEX(Inputs!$C$7:$E$7,1,$D5) -> 922.3 | K5: =IF($E5="Pending","",I5*J5) -> 609564.56 | L5: =INDEX(Inputs!$C$8:$E$8,1,$D5) -> 0.4 | M5: =IF($E5="Pending","",K5*L5) -> 243825.82 | N5: =IF($E5="Pending","",K5*(1-L5)) -> 365738.74 | O5: =INDEX(Inputs!$C$9:$E$9,1,$D5) -> 24.51 | P5: =INDEX(Inputs!$C$10:$E$10,1,$D5) -> 3 | Q5: =IF($E5="Pending","",(M5*O5+N5*P5)/100) -> 70733.872 | R5: =INDEX(Inputs!$C$12:$E$12,1,$D5) -> 11.4 | S5: =IF($E5="Pending","",I5*R5) -> 7534.4638 | T5: =IF($E5="Pending","",Q5-S5) -> 63199.408 | U5: =INDEX(Inputs!$C$11:$E$11,1,$D5) -> 1100 | V5: =IF($E5="Pending","",I5*U5) -> 727009.67 | W5: =IF($E5="Pending","",IF(T5<=0,"No payback",V5/T5)) -> 11.503425 | X5: =INDEX(Inputs!$C$13:$E$13,1,$D5) -> 0.13096 | Y5: =IF($E5="Pending","",K5*X5/1000) -> 79.828575
A6: 1 | B6: Unipart | C6: Central | D6: 2 | E6: =Results!$I$6 -> Sized | F6: =Results!$G$6 -> 9774 | G6: =INDEX(Inputs!$C$5:$E$5,1,$D6) -> 0.4 | H6: =INDEX(Inputs!$C$6:$E$6,1,$D6) -> 230 | I6: =IF($E6="Pending","",F6*G6*H6/1000) -> 899.208 | J6: =INDEX(Inputs!$C$7:$E$7,1,$D6) -> 922.3 | K6: =IF($E6="Pending","",I6*J6) -> 829339.54 | L6: =INDEX(Inputs!$C$8:$E$8,1,$D6) -> 0.6 | M6: =IF($E6="Pending","",K6*L6) -> 497603.72 | N6: =IF($E6="Pending","",K6*(1-L6)) -> 331735.82 | O6: =INDEX(Inputs!$C$9:$E$9,1,$D6) -> 24.51 | P6: =INDEX(Inputs!$C$10:$E$10,1,$D6) -> 4.1 | Q6: =IF($E6="Pending","",(M6*O6+N6*P6)/100) -> 135563.84 | R6: =INDEX(Inputs!$C$12:$E$12,1,$D6) -> 9.5 | S6: =IF($E6="Pending","",I6*R6) -> 8542.476 | T6: =IF($E6="Pending","",Q6-S6) -> 127021.36 | U6: =INDEX(Inputs!$C$11:$E$11,1,$D6) -> 900 | V6: =IF($E6="Pending","",I6*U6) -> 809287.2 | W6: =IF($E6="Pending","",IF(T6<=0,"No payback",V6/T6)) -> 6.3712683 | X6: =INDEX(Inputs!$C$13:$E$13,1,$D6) -> 0.13096 | Y6: =IF($E6="Pending","",K6*X6/1000) -> 108.61031
A7: 1 | B7: Unipart | C7: High | D7: 3 | E7: =Results!$I$6 -> Sized | F7: =Results!$G$6 -> 9774 | G7: =INDEX(Inputs!$C$5:$E$5,1,$D7) -> 0.462 | H7: =INDEX(Inputs!$C$6:$E$6,1,$D7) -> 230 | I7: =IF($E7="Pending","",F7*G7*H7/1000) -> 1038.5852 | J7: =INDEX(Inputs!$C$7:$E$7,1,$D7) -> 922.3 | K7: =IF($E7="Pending","",I7*J7) -> 957887.17 | L7: =INDEX(Inputs!$C$8:$E$8,1,$D7) -> 0.8 | M7: =IF($E7="Pending","",K7*L7) -> 766309.73 | N7: =IF($E7="Pending","",K7*(1-L7)) -> 191577.43 | O7: =INDEX(Inputs!$C$9:$E$9,1,$D7) -> 24.51 | P7: =INDEX(Inputs!$C$10:$E$10,1,$D7) -> 4.1 | Q7: =IF($E7="Pending","",(M7*O7+N7*P7)/100) -> 195677.19 | R7: =INDEX(Inputs!$C$12:$E$12,1,$D7) -> 7.6 | S7: =IF($E7="Pending","",I7*R7) -> 7893.2478 | T7: =IF($E7="Pending","",Q7-S7) -> 187783.94 | U7: =INDEX(Inputs!$C$11:$E$11,1,$D7) -> 700 | V7: =IF($E7="Pending","",I7*U7) -> 727009.67 | W7: =IF($E7="Pending","",IF(T7<=0,"No payback",V7/T7)) -> 3.871522 | X7: =INDEX(Inputs!$C$13:$E$13,1,$D7) -> 0.13096 | Y7: =IF($E7="Pending","",K7*X7/1000) -> 125.4449
A8: 11 | B8: Unipart Logistics Cowley | C8: Low | D8: 1 | E8: =Results!$I$7 -> Pending | F8: =Results!$G$7 -> 80278 | G8: =INDEX(Inputs!$C$5:$E$5,1,$D8) -> 0.294 | H8: =INDEX(Inputs!$C$6:$E$6,1,$D8) -> 230 | I8: =IF($E8="Pending","",F8*G8*H8/1000) | J8: =INDEX(Inputs!$C$7:$E$7,1,$D8) -> 922.3 | K8: =IF($E8="Pending","",I8*J8) | L8: =INDEX(Inputs!$C$8:$E$8,1,$D8) -> 0.4 | M8: =IF($E8="Pending","",K8*L8) | N8: =IF($E8="Pending","",K8*(1-L8)) | O8: =INDEX(Inputs!$C$9:$E$9,1,$D8) -> 24.51 | P8: =INDEX(Inputs!$C$10:$E$10,1,$D8) -> 3 | Q8: =IF($E8="Pending","",(M8*O8+N8*P8)/100) | R8: =INDEX(Inputs!$C$12:$E$12,1,$D8) -> 11.4 | S8: =IF($E8="Pending","",I8*R8) | T8: =IF($E8="Pending","",Q8-S8) | U8: =INDEX(Inputs!$C$11:$E$11,1,$D8) -> 1100 | V8: =IF($E8="Pending","",I8*U8) | W8: =IF($E8="Pending","",IF(T8<=0,"No payback",V8/T8)) | X8: =INDEX(Inputs!$C$13:$E$13,1,$D8) -> 0.13096 | Y8: =IF($E8="Pending","",K8*X8/1000)
A9: 11 | B9: Unipart Logistics Cowley | C9: Central | D9: 2 | E9: =Results!$I$7 -> Pending | F9: =Results!$G$7 -> 80278 | G9: =INDEX(Inputs!$C$5:$E$5,1,$D9) -> 0.4 | H9: =INDEX(Inputs!$C$6:$E$6,1,$D9) -> 230 | I9: =IF($E9="Pending","",F9*G9*H9/1000) | J9: =INDEX(Inputs!$C$7:$E$7,1,$D9) -> 922.3 | K9: =IF($E9="Pending","",I9*J9) | L9: =INDEX(Inputs!$C$8:$E$8,1,$D9) -> 0.6 | M9: =IF($E9="Pending","",K9*L9) | N9: =IF($E9="Pending","",K9*(1-L9)) | O9: =INDEX(Inputs!$C$9:$E$9,1,$D9) -> 24.51 | P9: =INDEX(Inputs!$C$10:$E$10,1,$D9) -> 4.1 | Q9: =IF($E9="Pending","",(M9*O9+N9*P9)/100) | R9: =INDEX(Inputs!$C$12:$E$12,1,$D9) -> 9.5 | S9: =IF($E9="Pending","",I9*R9) | T9: =IF($E9="Pending","",Q9-S9) | U9: =INDEX(Inputs!$C$11:$E$11,1,$D9) -> 900 | V9: =IF($E9="Pending","",I9*U9) | W9: =IF($E9="Pending","",IF(T9<=0,"No payback",V9/T9)) | X9: =INDEX(Inputs!$C$13:$E$13,1,$D9) -> 0.13096 | Y9: =IF($E9="Pending","",K9*X9/1000)
A10: 11 | B10: Unipart Logistics Cowley | C10: High | D10: 3 | E10: =Results!$I$7 -> Pending | F10: =Results!$G$7 -> 80278 | G10: =INDEX(Inputs!$C$5:$E$5,1,$D10) -> 0.462 | H10: =INDEX(Inputs!$C$6:$E$6,1,$D10) -> 230 | I10: =IF($E10="Pending","",F10*G10*H10/1000) | J10: =INDEX(Inputs!$C$7:$E$7,1,$D10) -> 922.3 | K10: =IF($E10="Pending","",I10*J10) | L10: =INDEX(Inputs!$C$8:$E$8,1,$D10) -> 0.8 | M10: =IF($E10="Pending","",K10*L10) | N10: =IF($E10="Pending","",K10*(1-L10)) | O10: =INDEX(Inputs!$C$9:$E$9,1,$D10) -> 24.51 | P10: =INDEX(Inputs!$C$10:$E$10,1,$D10) -> 4.1 | Q10: =IF($E10="Pending","",(M10*O10+N10*P10)/100) | R10: =INDEX(Inputs!$C$12:$E$12,1,$D10) -> 7.6 | S10: =IF($E10="Pending","",I10*R10) | T10: =IF($E10="Pending","",Q10-S10) | U10: =INDEX(Inputs!$C$11:$E$11,1,$D10) -> 700 | V10: =IF($E10="Pending","",I10*U10) | W10: =IF($E10="Pending","",IF(T10<=0,"No payback",V10/T10)) | X10: =INDEX(Inputs!$C$13:$E$13,1,$D10) -> 0.13096 | Y10: =IF($E10="Pending","",K10*X10/1000)
A11: 12 | B11: Sainsbury's | C11: Low | D11: 1 | E11: =Results!$I$8 -> Sized | F11: =Results!$G$8 -> 5488 | G11: =INDEX(Inputs!$C$5:$E$5,1,$D11) -> 0.294 | H11: =INDEX(Inputs!$C$6:$E$6,1,$D11) -> 230 | I11: =IF($E11="Pending","",F11*G11*H11/1000) -> 371.09856 | J11: =INDEX(Inputs!$C$7:$E$7,1,$D11) -> 922.3 | K11: =IF($E11="Pending","",I11*J11) -> 342264.2 | L11: =INDEX(Inputs!$C$8:$E$8,1,$D11) -> 0.4 | M11: =IF($E11="Pending","",K11*L11) -> 136905.68 | N11: =IF($E11="Pending","",K11*(1-L11)) -> 205358.52 | O11: =INDEX(Inputs!$C$9:$E$9,1,$D11) -> 24.51 | P11: =INDEX(Inputs!$C$10:$E$10,1,$D11) -> 3 | Q11: =IF($E11="Pending","",(M11*O11+N11*P11)/100) -> 39716.338 | R11: =INDEX(Inputs!$C$12:$E$12,1,$D11) -> 11.4 | S11: =IF($E11="Pending","",I11*R11) -> 4230.5236 | T11: =IF($E11="Pending","",Q11-S11) -> 35485.814 | U11: =INDEX(Inputs!$C$11:$E$11,1,$D11) -> 1100 | V11: =IF($E11="Pending","",I11*U11) -> 408208.42 | W11: =IF($E11="Pending","",IF(T11<=0,"No payback",V11/T11)) -> 11.503425 | X11: =INDEX(Inputs!$C$13:$E$13,1,$D11) -> 0.13096 | Y11: =IF($E11="Pending","",K11*X11/1000) -> 44.82292
A12: 12 | B12: Sainsbury's | C12: Central | D12: 2 | E12: =Results!$I$8 -> Sized | F12: =Results!$G$8 -> 5488 | G12: =INDEX(Inputs!$C$5:$E$5,1,$D12) -> 0.4 | H12: =INDEX(Inputs!$C$6:$E$6,1,$D12) -> 230 | I12: =IF($E12="Pending","",F12*G12*H12/1000) -> 504.896 | J12: =INDEX(Inputs!$C$7:$E$7,1,$D12) -> 922.3 | K12: =IF($E12="Pending","",I12*J12) -> 465665.58 | L12: =INDEX(Inputs!$C$8:$E$8,1,$D12) -> 0.6 | M12: =IF($E12="Pending","",K12*L12) -> 279399.35 | N12: =IF($E12="Pending","",K12*(1-L12)) -> 186266.23 | O12: =INDEX(Inputs!$C$9:$E$9,1,$D12) -> 24.51 | P12: =INDEX(Inputs!$C$10:$E$10,1,$D12) -> 4.1 | Q12: =IF($E12="Pending","",(M12*O12+N12*P12)/100) -> 76117.696 | R12: =INDEX(Inputs!$C$12:$E$12,1,$D12) -> 9.5 | S12: =IF($E12="Pending","",I12*R12) -> 4796.512 | T12: =IF($E12="Pending","",Q12-S12) -> 71321.184 | U12: =INDEX(Inputs!$C$11:$E$11,1,$D12) -> 900 | V12: =IF($E12="Pending","",I12*U12) -> 454406.4 | W12: =IF($E12="Pending","",IF(T12<=0,"No payback",V12/T12)) -> 6.3712683 | X12: =INDEX(Inputs!$C$13:$E$13,1,$D12) -> 0.13096 | Y12: =IF($E12="Pending","",K12*X12/1000) -> 60.983564
A13: 12 | B13: Sainsbury's | C13: High | D13: 3 | E13: =Results!$I$8 -> Sized | F13: =Results!$G$8 -> 5488 | G13: =INDEX(Inputs!$C$5:$E$5,1,$D13) -> 0.462 | H13: =INDEX(Inputs!$C$6:$E$6,1,$D13) -> 230 | I13: =IF($E13="Pending","",F13*G13*H13/1000) -> 583.15488 | J13: =INDEX(Inputs!$C$7:$E$7,1,$D13) -> 922.3 | K13: =IF($E13="Pending","",I13*J13) -> 537843.75 | L13: =INDEX(Inputs!$C$8:$E$8,1,$D13) -> 0.8 | M13: =IF($E13="Pending","",K13*L13) -> 430275 | N13: =IF($E13="Pending","",K13*(1-L13)) -> 107568.75 | O13: =INDEX(Inputs!$C$9:$E$9,1,$D13) -> 24.51 | P13: =INDEX(Inputs!$C$10:$E$10,1,$D13) -> 4.1 | Q13: =IF($E13="Pending","",(M13*O13+N13*P13)/100) -> 109870.72 | R13: =INDEX(Inputs!$C$12:$E$12,1,$D13) -> 7.6 | S13: =IF($E13="Pending","",I13*R13) -> 4431.9771 | T13: =IF($E13="Pending","",Q13-S13) -> 105438.74 | U13: =INDEX(Inputs!$C$11:$E$11,1,$D13) -> 700 | V13: =IF($E13="Pending","",I13*U13) -> 408208.42 | W13: =IF($E13="Pending","",IF(T13<=0,"No payback",V13/T13)) -> 3.871522 | X13: =INDEX(Inputs!$C$13:$E$13,1,$D13) -> 0.13096 | Y13: =IF($E13="Pending","",K13*X13/1000) -> 70.436017
A14: 50 | B14: Ozone Leisure Centre | C14: Low | D14: 1 | E14: =Results!$I$9 -> Sized | F14: =Results!$G$9 -> 11652 | G14: =INDEX(Inputs!$C$5:$E$5,1,$D14) -> 0.294 | H14: =INDEX(Inputs!$C$6:$E$6,1,$D14) -> 230 | I14: =IF($E14="Pending","",F14*G14*H14/1000) -> 787.90824 | J14: =INDEX(Inputs!$C$7:$E$7,1,$D14) -> 922.3 | K14: =IF($E14="Pending","",I14*J14) -> 726687.77 | L14: =INDEX(Inputs!$C$8:$E$8,1,$D14) -> 0.4 | M14: =IF($E14="Pending","",K14*L14) -> 290675.11 | N14: =IF($E14="Pending","",K14*(1-L14)) -> 436012.66 | O14: =INDEX(Inputs!$C$9:$E$9,1,$D14) -> 24.51 | P14: =INDEX(Inputs!$C$10:$E$10,1,$D14) -> 3 | Q14: =IF($E14="Pending","",(M14*O14+N14*P14)/100) -> 84324.849 | R14: =INDEX(Inputs!$C$12:$E$12,1,$D14) -> 11.4 | S14: =IF($E14="Pending","",I14*R14) -> 8982.1539 | T14: =IF($E14="Pending","",Q14-S14) -> 75342.695 | U14: =INDEX(Inputs!$C$11:$E$11,1,$D14) -> 1100 | V14: =IF($E14="Pending","",I14*U14) -> 866699.06 | W14: =IF($E14="Pending","",IF(T14<=0,"No payback",V14/T14)) -> 11.503425 | X14: =INDEX(Inputs!$C$13:$E$13,1,$D14) -> 0.13096 | Y14: =IF($E14="Pending","",K14*X14/1000) -> 95.16703
A15: 50 | B15: Ozone Leisure Centre | C15: Central | D15: 2 | E15: =Results!$I$9 -> Sized | F15: =Results!$G$9 -> 11652 | G15: =INDEX(Inputs!$C$5:$E$5,1,$D15) -> 0.4 | H15: =INDEX(Inputs!$C$6:$E$6,1,$D15) -> 230 | I15: =IF($E15="Pending","",F15*G15*H15/1000) -> 1071.984 | J15: =INDEX(Inputs!$C$7:$E$7,1,$D15) -> 922.3 | K15: =IF($E15="Pending","",I15*J15) -> 988690.84 | L15: =INDEX(Inputs!$C$8:$E$8,1,$D15) -> 0.6 | M15: =IF($E15="Pending","",K15*L15) -> 593214.51 | N15: =IF($E15="Pending","",K15*(1-L15)) -> 395476.34 | O15: =INDEX(Inputs!$C$9:$E$9,1,$D15) -> 24.51 | P15: =INDEX(Inputs!$C$10:$E$10,1,$D15) -> 4.1 | Q15: =IF($E15="Pending","",(M15*O15+N15*P15)/100) -> 161611.41 | R15: =INDEX(Inputs!$C$12:$E$12,1,$D15) -> 9.5 | S15: =IF($E15="Pending","",I15*R15) -> 10183.848 | T15: =IF($E15="Pending","",Q15-S15) -> 151427.56 | U15: =INDEX(Inputs!$C$11:$E$11,1,$D15) -> 900 | V15: =IF($E15="Pending","",I15*U15) -> 964785.6 | W15: =IF($E15="Pending","",IF(T15<=0,"No payback",V15/T15)) -> 6.3712683 | X15: =INDEX(Inputs!$C$13:$E$13,1,$D15) -> 0.13096 | Y15: =IF($E15="Pending","",K15*X15/1000) -> 129.47895
A16: 50 | B16: Ozone Leisure Centre | C16: High | D16: 3 | E16: =Results!$I$9 -> Sized | F16: =Results!$G$9 -> 11652 | G16: =INDEX(Inputs!$C$5:$E$5,1,$D16) -> 0.462 | H16: =INDEX(Inputs!$C$6:$E$6,1,$D16) -> 230 | I16: =IF($E16="Pending","",F16*G16*H16/1000) -> 1238.1415 | J16: =INDEX(Inputs!$C$7:$E$7,1,$D16) -> 922.3 | K16: =IF($E16="Pending","",I16*J16) -> 1141937.9 | L16: =INDEX(Inputs!$C$8:$E$8,1,$D16) -> 0.8 | M16: =IF($E16="Pending","",K16*L16) -> 913550.34 | N16: =IF($E16="Pending","",K16*(1-L16)) -> 228387.58 | O16: =INDEX(Inputs!$C$9:$E$9,1,$D16) -> 24.51 | P16: =INDEX(Inputs!$C$10:$E$10,1,$D16) -> 4.1 | Q16: =IF($E16="Pending","",(M16*O16+N16*P16)/100) -> 233275.08 | R16: =INDEX(Inputs!$C$12:$E$12,1,$D16) -> 7.6 | S16: =IF($E16="Pending","",I16*R16) -> 9409.8756 | T16: =IF($E16="Pending","",Q16-S16) -> 223865.2 | U16: =INDEX(Inputs!$C$11:$E$11,1,$D16) -> 700 | V16: =IF($E16="Pending","",I16*U16) -> 866699.06 | W16: =IF($E16="Pending","",IF(T16<=0,"No payback",V16/T16)) -> 3.871522 | X16: =INDEX(Inputs!$C$13:$E$13,1,$D16) -> 0.13096 | Y16: =IF($E16="Pending","",K16*X16/1000) -> 149.54819
A17: 26 | B17: Kassam Stadium | C17: Low | D17: 1 | E17: =Results!$I$10 -> Sized | F17: =Results!$G$10 -> 5428 | G17: =INDEX(Inputs!$C$5:$E$5,1,$D17) -> 0.294 | H17: =INDEX(Inputs!$C$6:$E$6,1,$D17) -> 230 | I17: =IF($E17="Pending","",F17*G17*H17/1000) -> 367.04136 | J17: =INDEX(Inputs!$C$7:$E$7,1,$D17) -> 922.3 | K17: =IF($E17="Pending","",I17*J17) -> 338522.25 | L17: =INDEX(Inputs!$C$8:$E$8,1,$D17) -> 0.4 | M17: =IF($E17="Pending","",K17*L17) -> 135408.9 | N17: =IF($E17="Pending","",K17*(1-L17)) -> 203113.35 | O17: =INDEX(Inputs!$C$9:$E$9,1,$D17) -> 24.51 | P17: =INDEX(Inputs!$C$10:$E$10,1,$D17) -> 3 | Q17: =IF($E17="Pending","",(M17*O17+N17*P17)/100) -> 39282.121 | R17: =INDEX(Inputs!$C$12:$E$12,1,$D17) -> 11.4 | S17: =IF($E17="Pending","",I17*R17) -> 4184.2715 | T17: =IF($E17="Pending","",Q17-S17) -> 35097.85 | U17: =INDEX(Inputs!$C$11:$E$11,1,$D17) -> 1100 | V17: =IF($E17="Pending","",I17*U17) -> 403745.5 | W17: =IF($E17="Pending","",IF(T17<=0,"No payback",V17/T17)) -> 11.503425 | X17: =INDEX(Inputs!$C$13:$E$13,1,$D17) -> 0.13096 | Y17: =IF($E17="Pending","",K17*X17/1000) -> 44.332873
A18: 26 | B18: Kassam Stadium | C18: Central | D18: 2 | E18: =Results!$I$10 -> Sized | F18: =Results!$G$10 -> 5428 | G18: =INDEX(Inputs!$C$5:$E$5,1,$D18) -> 0.4 | H18: =INDEX(Inputs!$C$6:$E$6,1,$D18) -> 230 | I18: =IF($E18="Pending","",F18*G18*H18/1000) -> 499.376 | J18: =INDEX(Inputs!$C$7:$E$7,1,$D18) -> 922.3 | K18: =IF($E18="Pending","",I18*J18) -> 460574.48 | L18: =INDEX(Inputs!$C$8:$E$8,1,$D18) -> 0.6 | M18: =IF($E18="Pending","",K18*L18) -> 276344.69 | N18: =IF($E18="Pending","",K18*(1-L18)) -> 184229.79 | O18: =INDEX(Inputs!$C$9:$E$9,1,$D18) -> 24.51 | P18: =INDEX(Inputs!$C$10:$E$10,1,$D18) -> 4.1 | Q18: =IF($E18="Pending","",(M18*O18+N18*P18)/100) -> 75285.505 | R18: =INDEX(Inputs!$C$12:$E$12,1,$D18) -> 9.5 | S18: =IF($E18="Pending","",I18*R18) -> 4744.072 | T18: =IF($E18="Pending","",Q18-S18) -> 70541.433 | U18: =INDEX(Inputs!$C$11:$E$11,1,$D18) -> 900 | V18: =IF($E18="Pending","",I18*U18) -> 449438.4 | W18: =IF($E18="Pending","",IF(T18<=0,"No payback",V18/T18)) -> 6.3712683 | X18: =INDEX(Inputs!$C$13:$E$13,1,$D18) -> 0.13096 | Y18: =IF($E18="Pending","",K18*X18/1000) -> 60.316835
A19: 26 | B19: Kassam Stadium | C19: High | D19: 3 | E19: =Results!$I$10 -> Sized | F19: =Results!$G$10 -> 5428 | G19: =INDEX(Inputs!$C$5:$E$5,1,$D19) -> 0.462 | H19: =INDEX(Inputs!$C$6:$E$6,1,$D19) -> 230 | I19: =IF($E19="Pending","",F19*G19*H19/1000) -> 576.77928 | J19: =INDEX(Inputs!$C$7:$E$7,1,$D19) -> 922.3 | K19: =IF($E19="Pending","",I19*J19) -> 531963.53 | L19: =INDEX(Inputs!$C$8:$E$8,1,$D19) -> 0.8 | M19: =IF($E19="Pending","",K19*L19) -> 425570.82 | N19: =IF($E19="Pending","",K19*(1-L19)) -> 106392.71 | O19: =INDEX(Inputs!$C$9:$E$9,1,$D19) -> 24.51 | P19: =INDEX(Inputs!$C$10:$E$10,1,$D19) -> 4.1 | Q19: =IF($E19="Pending","",(M19*O19+N19*P19)/100) -> 108669.51 | R19: =INDEX(Inputs!$C$12:$E$12,1,$D19) -> 7.6 | S19: =IF($E19="Pending","",I19*R19) -> 4383.5225 | T19: =IF($E19="Pending","",Q19-S19) -> 104285.99 | U19: =INDEX(Inputs!$C$11:$E$11,1,$D19) -> 700 | V19: =IF($E19="Pending","",I19*U19) -> 403745.5 | W19: =IF($E19="Pending","",IF(T19<=0,"No payback",V19/T19)) -> 3.871522 | X19: =INDEX(Inputs!$C$13:$E$13,1,$D19) -> 0.13096 | Y19: =IF($E19="Pending","",K19*X19/1000) -> 69.665944
A20: 13 | B20: Holiday Inn | C20: Low | D20: 1 | E20: =Results!$I$11 -> Sized | F20: =Results!$G$11 -> 4424 | G20: =INDEX(Inputs!$C$5:$E$5,1,$D20) -> 0.294 | H20: =INDEX(Inputs!$C$6:$E$6,1,$D20) -> 230 | I20: =IF($E20="Pending","",F20*G20*H20/1000) -> 299.15088 | J20: =INDEX(Inputs!$C$7:$E$7,1,$D20) -> 922.3 | K20: =IF($E20="Pending","",I20*J20) -> 275906.86 | L20: =INDEX(Inputs!$C$8:$E$8,1,$D20) -> 0.4 | M20: =IF($E20="Pending","",K20*L20) -> 110362.74 | N20: =IF($E20="Pending","",K20*(1-L20)) -> 165544.11 | O20: =INDEX(Inputs!$C$9:$E$9,1,$D20) -> 24.51 | P20: =INDEX(Inputs!$C$10:$E$10,1,$D20) -> 3 | Q20: =IF($E20="Pending","",(M20*O20+N20*P20)/100) -> 32016.232 | R20: =INDEX(Inputs!$C$12:$E$12,1,$D20) -> 11.4 | S20: =IF($E20="Pending","",I20*R20) -> 3410.32 | T20: =IF($E20="Pending","",Q20-S20) -> 28605.912 | U20: =INDEX(Inputs!$C$11:$E$11,1,$D20) -> 1100 | V20: =IF($E20="Pending","",I20*U20) -> 329065.97 | W20: =IF($E20="Pending","",IF(T20<=0,"No payback",V20/T20)) -> 11.503425 | X20: =INDEX(Inputs!$C$13:$E$13,1,$D20) -> 0.13096 | Y20: =IF($E20="Pending","",K20*X20/1000) -> 36.132762
